Workbook

Sheet Assumptions
A1: INPUTS — edit yellow cells to recalculate everything downstream
A3: Parameter | B3: Value | C3: Unit | D3: Notes
A4: Enterprise monthly revenue | B4: 4500 | C4: USD | D4: Customer pays this per month
A5: Credit sale price | B5: 0.00099 | C5: USD/credit | D5: From Pro plan: $99 / 100K credits
A6: Target gross margin (low) | B6: 0.6 | C6: % | D6: 60%
A7: Target gross margin (mid) | B7: 0.7 | C7: % | D7: 70%
A8: Target gross margin (high) | B8: 0.8 | C8: % | D8: 80%
A9: Fixed infra share / customer | B9: 180 | C9: USD/month | D9: ECS + NAT + MemoryDB + Aurora + Datadog + Temporal
A11: CODEBASE: credits per trace | B11: 1 | C11: credits | D11: ACTION_CREDITS.trace
A12: CODEBASE: credits per flagger-scan | B12: 30 | C12: credits | D12: ACTION_CREDITS.flagger-scan
A13: CODEBASE: credits per live-eval-scan | B13: 30 | C13: credits | D13: ACTION_CREDITS.live-eval-scan
A14: CODEBASE: credits per eval-generation | B14: 1000 | C14: credits | D14: ACTION_CREDITS.eval-generation (GEPA)
A16: Real cost per trace (CH + S3) | B16: 0.0001 | C16: USD/trace | D16: ClickHouse write + S3 share
A17: Real cost per flagger-scan | B17: 0.011 | C17: USD/scan | D17: Haiku 4.5: 2 calls × (~6K in + 1K out) × ($1/M in + $5/M out)
... A26: Max GEPA per month (contract cap) | B26: 100 | C26: runs | D26: Recommended belt-and-suspenders limit
A28: ── PRICING CURVE INPUTS ──
A29: Floor price (anchor at 4.5M) | B29: 0.00099 | C29: USD/credit | D29: Cheapest price for largest commitment
A30: Ceiling price (small commits) | B30: 0.002 | C30: USD/credit | D30: Approaches Pro overage price
A31: Anchor volume for floor price | B31: 4500000 | C31: credits | D31: Volume where price hits floor

Sheet Derived
A1: DERIVED VALUES (calculated from Assumptions)
A3: Quantity | B3: Value | C3: Formula
A4: Total credit pool / month | B4: =Assumptions!$B$4/Assumptions!$B$5 | C4: Revenue / credit price
A5: COGS budget at 60% margin | B5: =Assumptions!$B$4*(1-Assumptions!$B$6) | C5: Revenue × (1 − margin)
A6: COGS budget at 70% margin | B6: =Assumptions!$B$4*(1-Assumptions!$B$7) | C6: Revenue × (1 − margin)
A7: COGS budget at 80% margin | B7: =Assumptions!$B$4*(1-Assumptions!$B$8) | C7: Revenue × (1 − margin)
A8: Variable budget @ 60% (after fixed) | B8: =Assumptions!$B$4*(1-Assumptions!$B$6)-Assumptions!$B$9 | C8: COGS − fixed infra share
A9: Variable budget @ 70% (after fixed) | B9: =Assumptions!$B$4*(1-Assumptions!$B$7)-Assumptions!$B$9
A10: Variable budget @ 80% (after fixed) | B10: =Assumptions!$B$4*(1-Assumptions!$B$8)-Assumptions!$B$9
A11: Voyage max spend (at cap) | B11: =Assumptions!$B$23/1000000*Assumptions!$B$21 | C11: Voyage cap × rate
A12: Cost-per-credit at 60% margin | B12: =(Assumptions!$B$4*(1-Assumptions!$B$6))/(Assumptions!$B$4/Assumptions!$B$5) | C12: COGS / credit pool
A13: Cost-per-credit at 70% margin | B13: =(Assumptions!$B$4*(1-Assumptions!$B$7))/(Assumptions!$B$4/Assumptions!$B$5)
A14: Cost-per-credit at 80% margin | B14: =(Assumptions!$B$4*(1-Assumptions!$B$8))/(Assumptions!$B$4/Assumptions!$B$5)

Sheet Operations
A1: PER-OPERATION ECONOMICS
A3: Operation | B3: Credits (codebase) | C3: Sale price / op | D3: Real cost / op | E3: Real cost / credit | F3: Margin per op | G3: Status
A4: trace | B4: =Assumptions!$B$11 | C4: =Assumptions!$B$11*Assumptions!$B$5 | D4: =Assumptions!$B$16 | E4: =Assumptions!$B$16/Assumptions!$B$11 | F4: =(Assumptions!$B$11*Assumptions!$B$5-Assumptions!$B$16)/(Assumptions!$B$11*Assumptions!$B$5) | G4: =IF(F4<0,"LOSS",IF(F4<0.5,"low margin","OK"))
A5: flagger-scan | B5: =Assumptions!$B$12 | C5: =Assumptions!$B$12*Assumptions!$B$5 | D5: =Assumptions!$B$17 | E5: =Assumptions!$B$17/Assumptions!$B$12 | F5: =(Assumptions!$B$12*Assumptions!$B$5-Assumptions!$B$17)/(Assumptions!$B$12*Assumptions!$B$5) | G5: =IF(F5<0,"LOSS",IF(F5<0.5,"low margin","OK"))
A6: live-eval-scan | B6: =Assumptions!$B$13 | C6: =Assumptions!$B$13*Assumptions!$B$5 | D6: =Assumptions!$B$18 | E6: =Assumptions!$B$18/Assumptions!$B$13 | F6: =(Assumptions!$B$13*Assumptions!$B$5-Assumptions!$B$18)/(Assumptions!$B$13*Assumptions!$B$5) | G6: =IF(F6<0,"LOSS",IF(F6<0.5,"low margin","OK"))
A7: eval-generation | B7: =Assumptions!$B$14 | C7: =Assumptions!$B$14*Assumptions!$B$5 | D7: =Assumptions!$B$19 | E7: =Assumptions!$B$19/Assumptions!$B$14 | F7: =(Assumptions!$B$14*Assumptions!$B$5-Assumptions!$B$19)/(Assumptions!$B$14*Assumptions!$B$5) | G7: =IF(F7<0,"LOSS",IF(F7<0.5,"low margin","OK"))

Sheet Worst-Case Scenarios
A1: WORST CASE: customer spends 100% of credits on one action
A3: All credits on… | B3: Operations | C3: Op cost | D3: Voyage drag | E3: Fixed | F3: Total COGS | G3: Margin
A4: 100% trace | B4: =Derived!$B$4/Assumptions!$B$11 | C4: =(Derived!$B$4/Assumptions!$B$11)*Assumptions!$B$16 | D4: =MIN(Derived!$B$4/Assumptions!$B$11*Assumptions!$B$22/1000000*Assumptions!$B$21,Derived!$B$11) | E4: =Assumptions!$B$9 | F4: =C4+D4+E4 | G4: =(Assumptions!$B$4-F4)/Assumptions!$B$4
A5: 100% flagger-scan | B5: =Derived!$B$4/Assumptions!$B$12 | C5: =(Derived!$B$4/Assumptions!$B$12)*Assumptions!$B$17 | D5: 0 | E5: =Assumptions!$B$9 | F5: =C5+D5+E5 | G5: =(Assumptions!$B$4-F5)/Assumptions!$B$4
A6: 100% live-eval-scan | B6: =Derived!$B$4/Assumptions!$B$13 | C6: =(Derived!$B$4/Assumptions!$B$13)*Assumptions!$B$18 | D6: 0 | E6: =Assumptions!$B$9 | F6: =C6+D6+E6 | G6: =(Assumptions!$B$4-F6)/Assumptions!$B$4
A7: 100% eval-generation (UNGATED) | B7: =Derived!$B$4/Assumptions!$B$14 | C7: =(Derived!$B$4/Assumptions!$B$14)*Assumptions!$B$19 | D7: 0 | E7: =Assumptions!$B$9 | F7: =C7+D7+E7 | G7: =(Assumptions!$B$4-F7)/Assumptions!$B$4
A8: GEPA-max via issue funnel | B8: =ROUNDDOWN(Derived!$B$4/(1+Assumptions!$B$14/Assumptions!$B$25)/Assumptions!$B$25,0) | C8: =B8*Assumptions!$B$19+(B8*Assumptions!$B$25)*Assumptions!$B$16 | D8: =MIN(B8*Assumptions!$B$25*Assumptions!$B$22/1000000*Assumptions!$B$21,Derived!$B$11) | E8: =Assumptions!$B$9 | F8: =C8+D8+E8 | G8: =(Assumptions!$B$4-F8)/Assumptions!$B$4
A9: GEPA capped at contract limit | B9: =Assumptions!$B$26 | C9: =Assumptions!$B$26*Assumptions!$B$19+(Derived!$B$4-Assumptions!$B$26*Assumptions!$B$14)*Assumptions!$B$16 | D9: =MIN((Derived!$B$4-Assumptions!$B$26*Assumptions!$B$14)*Assumptions!$B$22/1000000*Assumptions!$B$21,Derived!$B$11) | E9: =Assumptions!$B$9 | F9: =C9+D9+E9 | G9: =(Assumptions!$B$4-F9)/Assumptions!$B$4

Sheet Allocation Calculator
A1: MIXED ALLOCATION CALCULATOR — edit yellow % column
A3: Action | B3: % of credit pool | C3: Credits allocated | D3: Operations | E3: Real cost
A4: trace | B4: 0.6 | C4: =B4*Derived!$B$4 | D4: =C4/Assumptions!$B$11 | E4: =D4*Assumptions!$B$16
A5: live-eval-scan | B5: 0.25 | C5: =B5*Derived!$B$4 | D5: =C5/Assumptions!$B$13 | E5: =D5*Assumptions!$B$18
A6: flagger-scan | B6: 0.12 | C6: =B6*Derived!$B$4 | D6: =C6/Assumptions!$B$12 | E6: =D6*Assumptions!$B$17
A7: eval-generation | B7: 0.03 | C7: =B7*Derived!$B$4 | D7: =C7/Assumptions!$B$14 | E7: =D7*Assumptions!$B$19
A8: Σ allocation % | B8: =SUM(B4:B7) | E8: =SUM(E4:E7)
A10: Voyage spend (capped) | E10: =MIN(D4*Assumptions!$B$22/1000000*Assumptions!$B$21,Derived!$B$11)
A11: Fixed infra share | E11: =Assumptions!$B$9
A13: TOTAL COGS | E13: =SUM(E4:E7)+E10+E11
A14: Revenue | E14: =Assumptions!$B$4
A15: Gross profit | E15: =E14-E13
A16: Gross margin | E16: =(E14-E13)/E14

Sheet Codebase Reference
A1: WHERE THESE NUMBERS LIVE IN THE CODEBASE
A3: Concept | B3: Source file | C3: Symbol
A4: Credits per action | B4: packages/domain/billing/src/constants.ts | C4: ACTION_CREDITS
A5: Chargeable actions | B5: packages/domain/billing/src/constants.ts | C5: CHARGEABLE_ACTIONS
A6: Free plan config | B6: packages/domain/billing/src/constants.ts | C6: FREE_PLAN_CONFIG
A7: Pro plan config | B7: packages/domain/billing/src/constants.ts | C7: PRO_PLAN_CONFIG
A8: Enterprise plan config | B8: packages/domain/billing/src/constants.ts | C8: ENTERPRISE_PLAN_CONFIG
A9: Trace usage recording | B9: packages/domain/billing/src/use-cases/record-trace-usage-batch.ts | C9: recordTraceUsageBatch
A10: Bedrock/Anthropic pricing | B10: packages/domain/models/src/data/models.dev.json | C10: input/output (USD per 1M tokens)
A11: Cost computation | B11: packages/domain/models/src/entities/cost.ts | C11: estimateTotalCost / computeTokenCost
A12: Embedding budget caps | B12: packages/domain/spans/src/constants.ts | C12: EmbedBudgetResolver (5B tokens/month/org)
A13: Voyage embedding provider | B13: packages/platform/ai-voyage/src/ai.ts | C13: voyage-4-large
A14: Flagger workflow | B14: apps/workflows/src/workflows/flagger-workflow.ts | C14: flaggerWorkflow
... A18: Billing docs | B18: dev-docs/billing.md | C18: —

Sheet Feature Breakdown
A1: FEATURE-BY-FEATURE COST BREAKDOWN
A3: Feature | B3: Description | C3: Trigger / Path | D3: Credits | E3: Sale $/op | F3: Real cost/op | G3: Typical/mo | H3: Max/mo | I3: Notes
A4: ── INGESTION ──
A5: Trace ingestion | B5: OTLP spans batched into a trace; written to ClickHouse + S3 (>50KB) | C5: POST /v1/traces → BullMQ span-ingestion (50 workers) | D5: =Assumptions!$B$11 | E5: =Assumptions!$B$11*Assumptions!$B$5 | F5: =Assumptions!$B$16 | G5: 500000 | H5: 4500000 | I5: Voyage embedding auto-runs as side-effect (see below)
A6: Span storage (CH) | B6: Per-span row in ClickHouse spans table, ~2-5KB each | C6: Synchronous on every ingest | D6: — | E6: — | F6: — | G6: 100000000 | H6: 500000000 | I6: Rolled into trace ingestion cost — every trace already pays for its spans' CH write + storage
A7: S3 payload storage | B7: Raw OTLP payloads >50KB stored in latitude-{env}-spans bucket | C7: On ingest if payload exceeds inline limit | D7: — | E7: — | F7: 1e-05 | G7: 50 | H7: 5000 | I7: PUT request + ~100KB × $0.023/GB × 90d ≈ $0.00001/payload. Rare — only >50KB payloads
A8: ── EMBEDDINGS & SEARCH ──
A9: Voyage embedding | B9: voyage-4-large, 2048-dim, ~500-token chunks of conversation | C9: Side-effect of trace ingestion (budget-gated) | D9: — | E9: — | F9: =Assumptions!$B$22/1000000*Assumptions!$B$21 | G9: 500000 | H9: 2000000 | I9: HARD CAP: 5B tokens/org/month via EmbedBudgetResolver = $600 max
A10: Embedding storage (CH) | B10: trace_search_embeddings table; 2048 floats ≈ 8KB per chunk | C10: 30-day TTL on ClickHouse table | D10: — | E10: — | F10: — | G10: 2000000 | H10: 8000000 | I10: 8KB/chunk × $0.08/GB × 30d TTL ≈ $0.0000006/chunk — folded into CH storage rollup line
A11: Lexical docs (CH) | B11: trace_search_documents — full-text search via BM25 | C11: Same trigger as embeddings, no API cost | D11: — | E11: — | F11: — | G11: 2000000 | H11: 8000000 | I11: 1.5KB/chunk × $0.08/GB × 90d TTL ≈ $0.00000036/chunk + CH BM25 compute share — folded into CH storage + fixed-infra lines
A12: ── EVALUATIONS ──
A13: Live eval execution | B13: LLM-as-judge runs eval script against trace; minimax-m2.5 | C13: BullMQ live-evaluations:execute (50 workers, sampling-aware) | D13: =Assumptions!$B$13 | E13: =Assumptions!$B$13*Assumptions!$B$5 | F13: =Assumptions!$B$18 | G13: 50000 | H13: 150000 | I13: 1 Bedrock call per matched trace, ~1K tokens, low temperature
A14: Eval generation (GEPA) | B14: Auto-optimize eval script via GEPA; 100 examples × N candidates | C14: Temporal optimizeEvaluationWorkflow (1h activity) | D14: =Assumptions!$B$14 | E14: =Assumptions!$B$14*Assumptions!$B$5 | F14: =Assumptions!$B$19 | G14: 20 | H14: 100 | I14: REQUIRES ISSUES (which require traces) — natural gating
A15: Eval alignment refresh | B15: Re-score curated examples to update confusion matrix | C15: Manual API call OR hourly sweep — Temporal workflow | D15: — | E15: — | F15: 0.1 | G15: 10 | H15: 50 | I15: Cost folded into eval-generation; ~100 examples × $0.001 ≈ $0.10/run
A16: ── FLAGGERS ──
A17: Deterministic flagger | B17: Pattern matching on trace attributes — no LLM | C17: Synchronous in trace-end worker | D17: — | E17: — | F17: — | G17: 500000 | H17: 4500000 | I17: Pure CPU on existing ECS worker — no marginal cost; absorbed by fixed infra share
A18: Flagger LLM scan | B18: 2× Bedrock calls (classify + annotate) when matched | C18: Temporal flaggerWorkflow (rate-limited 30/60s/project) | D18: =Assumptions!$B$12 | E18: =Assumptions!$B$12*Assumptions!$B$5 | F18: =Assumptions!$B$17 | G18: 30000 | H18: 150000 | I18: Default sampling 10%; both temp=0/0.2, max 2048 tokens
A19: ── ISSUES & CLUSTERING ──
A20: Issue discovery | B20: Cluster traces into issues using centroid embeddings | C20: Temporal issueDiscoveryWorkflow on TracesIngested event | D20: — | E20: — | F20: 0.0003 | G20: 50 | H20: 4500 | I20: Temporal Cloud actions (~10-20 per workflow × $25/1M) + Postgres writes — small but non-zero
A21: Issue centroid update | B21: Running-sum of embeddings with 14-day half-life decay | C21: On every score assignment to issue | D21: — | E21: — | F21: — | G21: 1000 | H21: 50000 | I21: Postgres JSONB write only — absorbed by Aurora share in fixed infra; no Voyage call
A22: ── STORAGE ──
A23: ClickHouse (spans+traces) | B23: Primary OLAP store for all telemetry | C23: EBS gp3 storage, 365-day retention on enterprise | D23: — | E23: — | F23: 0.08 | G23: 500 | H23: 2500 | I23: GB/month; ~$0.08/GB on EBS — bundled into ECS bill
A24: ClickHouse (scores) | B24: score_analytics table — eval/annotation results | C24: Synchronous write on every eval run | D24: — | E24: — | F24: 0.08 | G24: 50 | H24: 500 | I24: GB/month; small relative to traces
A25: Postgres (metadata) | B25: Eval scripts, flagger configs, issues, billing events | C25: RLS-enforced multi-tenant Aurora Serverless | D25: — | E25: — | F25: 0.15 | G25: 5 | H25: 50 | I25: GB/month; metadata only — small but always-on
A26: ── FIXED INFRA (per-customer share) ──
A27: ECS Fargate (5 services) | B27: web/api/ingest/workers/workflows tasks | C27: Fixed monthly | D27: — | E27: — | F27: 80 | G27: — | H27: — | I27: Amortized across ~20 enterprises
A28: NAT Gateway + ALB | B28: ~$32 NAT + $16 ALB baseline | C28: Fixed monthly | D28: — | E28: — | F28: 5 | G28: — | H28: — | I28: Mostly fixed, minor data egress per customer
A29: MemoryDB (cache + BullMQ) | B29: 4 nodes × db.t4g.small | C29: Fixed monthly | D29: — | E29: — | F29: 25 | G29: — | H29: — | I29: Multi-AZ Redis 7
A30: Aurora Serverless v2 | B30: 0.5–2 ACU shared cluster | C30: Fixed monthly | D30: — | E30: — | F30: 30 | G30: — | H30: — | I30: Postgres metadata only
A31: CloudWatch + Datadog | B31: Log groups, container insights, synthetics | C31: Fixed monthly | D31: — | E31: — | F31: 10 | G31: — | H31: — | I31: Per-service log retention 30d
A32: Temporal Cloud | B32: Action-based pricing, eu-central-1 | C32: Fixed monthly | D32: — | E32: — | F32: 30 | G32: — | H32: — | I32: Workflows + activities billing
A33: Σ Fixed infra share | F33: =SUM(F27:F32) | I33: Matches 'Fixed infra share / customer' on Assumptions (currently =Assumptions!$B$9)
A35: ── ROLLUP: estimated monthly variable spend ──
A36: Component | B36: Cost basis | G36: Typical $ | H36: Max $ | I36: Note
A37: Trace ingest | B37: traces × Assumptions!$B$16 | G37: =500000*Assumptions!$B$16 | H37: =4500000*Assumptions!$B$16 | I37: Variable with volume
A38: Voyage embedding | B38: min(traces × Assumptions!$B$22/1M × Assumptions!$B$21, $600) | G38: =MIN(500000*Assumptions!$B$22/1000000*Assumptions!$B$21,Assumptions!$B$23/1000000*Assumptions!$B$21) | H38: =MIN(4500000*Assumptions!$B$22/1000000*Assumptions!$B$21,Assumptions!$B$23/1000000*Assumptions!$B$21) | I38: Capped at 5B Voyage tokens/mo
A39: Live eval | B39: runs × Assumptions!$B$18 | G39: =50000*Assumptions!$B$18 | H39: =150000*Assumptions!$B$18 | I39: Sampled subset of traces
A40: Flagger LLM | B40: scans × Assumptions!$B$17 | G40: =30000*Assumptions!$B$17 | H40: =150000*Assumptions!$B$17 | I40: 10% of matched traces
A41: Eval generation | B41: runs × Assumptions!$B$19 | G41: =20*Assumptions!$B$19 | H41: =100*Assumptions!$B$19 | I41: Gated by issues; cap at 100/mo
A42: CH + Postgres storage | B42: GB-mo across all tables | G42: 40 | H42: 200 | I42: Self-hosted on EBS
...

Sheet Pricing Tiers
A1: ENTERPRISE PRICING TIERS
A2: 4 tiers de Enterprise. Precio por crédito decrece linealmente entre ceiling y floor, tocando el floor en el anclaje (default 4.5M).
A4: Tier | B4: Créditos / mes | C4: Precio / crédito | D4: Revenue / mes | E4: COGS (mix default) | F4: Margen | G4: Ahorro vs ceiling | H4: Ahorro % | I4: Notas
A5: Enterprise Startup | B5: 1000000 | C5: =MAX(Assumptions!$B$29,Assumptions!$B$30-(Assumptions!$B$30-Assumptions!$B$29)*B5/Assumptions!$B$31) | D5: =B5*C5 | E5: =0.6*B5/Assumptions!$B$11*Assumptions!$B$16+MIN(0.6*B5/Assumptions!$B$11*Assumptions!$B$22/1000000*Assumptions!$B$21,Assumptions!$B$23/1000000*Assumptions!$B$21)+0.25*B5/Assumptions!$B$13*Assumptions!$B$18+0.12*B5/Assumptions!$B$12*Assumptions!$B$17+0.03*B5/Assumptions!$B$14*Assumptions!$B$19+Assumptions!$B$9 | F5: =(D5-E5)/D5 | G5: =B5*Assumptions!$B$30-D5 | H5: =(B5*Assumptions!$B$30-D5)/(B5*Assumptions!$B$30) | I5: Entry Enterprise — para startups/early-stage
A6: Enterprise S | B6: 2000000 | C6: =MAX(Assumptions!$B$29,Assumptions!$B$30-(Assumptions!$B$30-Assumptions!$B$29)*B6/Assumptions!$B$31) | D6: =B6*C6 | E6: =0.6*B6/Assumptions!$B$11*Assumptions!$B$16+MIN(0.6*B6/Assumptions!$B$11*Assumptions!$B$22/1000000*Assumptions!$B$21,Assumptions!$B$23/1000000*Assumptions!$B$21)+0.25*B6/Assumptions!$B$13*Assumptions!$B$18+0.12*B6/Assumptions!$B$12*Assumptions!$B$17+0.03*B6/Assumptions!$B$14*Assumptions!$B$19+Assumptions!$B$9 | F6: =(D6-E6)/D6 | G6: =B6*Assumptions!$B$30-D6 | H6: =(B6*Assumptions!$B$30-D6)/(B6*Assumptions!$B$30) | I6: Compromiso mínimo growth
A7: Enterprise M | B7: 4500000 | C7: =MAX(Assumptions!$B$29,Assumptions!$B$30-(Assumptions!$B$30-Assumptions!$B$29)*B7/Assumptions!$B$31) | D7: =B7*C7 | E7: =0.6*B7/Assumptions!$B$11*Assumptions!$B$16+MIN(0.6*B7/Assumptions!$B$11*Assumptions!$B$22/1000000*Assumptions!$B$21,Assumptions!$B$23/1000000*Assumptions!$B$21)+0.25*B7/Assumptions!$B$13*Assumptions!$B$18+0.12*B7/Assumptions!$B$12*Assumptions!$B$17+0.03*B7/Assumptions!$B$14*Assumptions!$B$19+Assumptions!$B$9 | F7: =(D7-E7)/D7 | G7: =B7*Assumptions!$B$30-D7 | H7: =(B7*Assumptions!$B$30-D7)/(B7*Assumptions!$B$30) | I7: Ancla — precio floor
A8: Enterprise L | B8: 10000000 | C8: =MAX(Assumptions!$B$29,Assumptions!$B$30-(Assumptions!$B$30-Assumptions!$B$29)*B8/Assumptions!$B$31) | D8: =B8*C8 | E8: =0.6*B8/Assumptions!$B$11*Assumptions!$B$16+MIN(0.6*B8/Assumptions!$B$11*Assumptions!$B$22/1000000*Assumptions!$B$21,Assumptions!$B$23/1000000*Assumptions!$B$21)+0.25*B8/Assumptions!$B$13*Assumptions!$B$18+0.12*B8/Assumptions!$B$12*Assumptions!$B$17+0.03*B8/Assumptions!$B$14*Assumptions!$B$19+Assumptions!$B$9 | F8: =(D8-E8)/D8 | G8: =B8*Assumptions!$B$30-D8 | H8: =(B8*Assumptions!$B$30-D8)/(B8*Assumptions!$B$30) | I8: Gran volumen — floor price aplica
A11: ── CALCULADORA CUSTOM ──
A12: Sales tool — meter cualquier volumen comprometido:
A13: Créditos / mes | B13: 3000000
A14: Precio / crédito | B14: =MAX(Assumptions!$B$29,Assumptions!$B$30-(Assumptions!$B$30-Assumptions!$B$29)*B13/Assumptions!$B$31)
A15: Revenue mensual | B15: =B13*B14
A16: COGS estimado | B16: =0.6*B13/Assumptions!$B$11*Assumptions!$B$16+MIN(0.6*B13/Assumptions!$B$11*Assumptions!$B$22/1000000*Assumptions!$B$21,Assumptions!$B$23/1000000*Assumptions!$B$21)+0.25*B13/Assumptions!$B$13*Assumptions!$B$18+0.12*B13/Assumptions!$B$12*Assumptions!$B$17+0.03*B13/Assumptions!$B$14*Assumptions!$B$19+Assumptions!$B$9
A17: Margen bruto | B17: =(B15-B16)/B15
